Running tests with local test database...
ERROR: usage: __main__.py [options] [file_or_dir] [file_or_dir] [...]
__main__.py: error: unrecognized arguments: tail -500 test_output.txt
  inifile: /home/omar/Documents/ruleIQ/pytest.ini
  rootdir: /home/omar/Documents/ruleIQ

